Workbook

Sheet dados_brutos
A1: Algoritmo | B1: Alunos | C1: Execucao | D1: Tempo | E1: Comparacoes | F1: Tempo Num
A2: Bubble | B2: 1000 | C2: 1 | D2: 0.006000 | E2: 499500 | F2: =VALUE(SUBSTITUTE(D2,".",",")) -> 0.006
A3: Bubble | B3: 1000 | C3: 2 | D3: 0.006000 | E3: 499500 | F3: =VALUE(SUBSTITUTE(D3,".",",")) -> 0.006
A4: Bubble | B4: 1000 | C4: 3 | D4: 0.005000 | E4: 499500 | F4: =VALUE(SUBSTITUTE(D4,".",",")) -> 0.005
A5: Bubble | B5: 1000 | C5: 4 | D5: 0.005000 | E5: 499500 | F5: =VALUE(SUBSTITUTE(D5,".",",")) -> 0.005
A6: Bubble | B6: 1000 | C6: 5 | D6: 0.006000 | E6: 499500 | F6: =VALUE(SUBSTITUTE(D6,".",",")) -> 0.006
A7: Bubble | B7: 10000 | C7: 1 | D7: 0.572000 | E7: 49995000 | F7: =VALUE(SUBSTITUTE(D7,".",",")) -> 0.572
A8: Bubble | B8: 10000 | C8: 2 | D8: 0.567000 | E8: 49995000 | F8: =VALUE(SUBSTITUTE(D8,".",",")) -> 0.567
A9: Bubble | B9: 10000 | C9: 3 | D9: 0.568000 | E9: 49995000 | F9: =VALUE(SUBSTITUTE(D9,".",",")) -> 0.568
A10: Bubble | B10: 10000 | C10: 4 | D10: 0.600000 | E10: 49995000 | F10: =VALUE(SUBSTITUTE(D10,".",",")) -> 0.6
A11: Bubble | B11: 10000 | C11: 5 | D11: 0.574000 | E11: 49995000 | F11: =VALUE(SUBSTITUTE(D11,".",",")) -> 0.574
A12: Bubble | B12: 100000 | C12: 1 | D12: 85391000 | E12: 4999950000 | F12: 85.391
A13: Bubble | B13: 100000 | C13: 2 | D13: 94235000 | E13: 4999950000 | F13: 94.235
A14: Bubble | B14: 100000 | C14: 3 | D14: 80723000 | E14: 4999950000 | F14: 80.723
A15: Bubble | B15: 100000 | C15: 4 | D15: 80441000 | E15: 4999950000 | F15: 80.441
A16: Bubble | B16: 100000 | C16: 5 | D16: 81582000 | E16: 4999950000 | F16: 81.582
A17: Bubble | B17: 200000 | C17: 1 | D17: 372495000 | E17: 19999900000 | F17: 372.495
A18: Bubble | B18: 200000 | C18: 2 | D18: 356639000 | E18: 19999900000 | F18: 356.639
A19: Bubble | B19: 200000 | C19: 3 | D19: 363973000 | E19: 19999900000 | F19: 363.973
A20: Bubble | B20: 200000 | C20: 4 | D20: 361800000 | E20: 19999900000 | F20: 361.8
A21: Bubble | B21: 200000 | C21: 5 | D21: 362569000 | E21: 19999900000 | F21: 362.569
A22: Merge | B22: 1000 | C22: 1 | D22: 0.001000 | E22: 8679 | F22: =VALUE(SUBSTITUTE(D22,".",",")) -> 0.001
A23: Merge | B23: 1000 | C23: 2 | D23: 0.001000 | E23: 8699 | F23: =VALUE(SUBSTITUTE(D23,".",",")) -> 0.001
A24: Merge | B24: 1000 | C24: 3 | D24: 0.001000 | E24: 8719 | F24: =VALUE(SUBSTITUTE(D24,".",",")) -> 0.001
A25: Merge | B25: 1000 | C25: 4 | D25: 0.001000 | E25: 8679 | F25: =VALUE(SUBSTITUTE(D25,".",",")) -> 0.001
A26: Merge | B26: 1000 | C26: 5 | D26: 0.000000 | E26: 8697 | F26: =VALUE(SUBSTITUTE(D26,".",",")) -> 0
A27: Merge | B27: 10000 | C27: 1 | D27: 0.006000 | E27: 120330 | F27: =VALUE(SUBSTITUTE(D27,".",",")) -> 0.006
A28: Merge | B28: 10000 | C28: 2 | D28: 0.006000 | E28: 120422 | F28: =VALUE(SUBSTITUTE(D28,".",",")) -> 0.006
A29: Merge | B29: 10000 | C29: 3 | D29: 0.006000 | E29: 120239 | F29: =VALUE(SUBSTITUTE(D29,".",",")) -> 0.006
A30: Merge | B30: 10000 | C30: 4 | D30: 0.006000 | E30: 120211 | F30: =VALUE(SUBSTITUTE(D30,".",",")) -> 0.006
A31: Merge | B31: 10000 | C31: 5 | D31: 0.005000 | E31: 120207 | F31: =VALUE(SUBSTITUTE(D31,".",",")) -> 0.005
A32: Merge | B32: 100000 | C32: 1 | D32: 0.074000 | E32: 1532482 | F32: =VALUE(SUBSTITUTE(D32,".",",")) -> 0.074
A33: Merge | B33: 100000 | C33: 2 | D33: 0.065000 | E33: 1533115 | F33: =VALUE(SUBSTITUTE(D33,".",",")) -> 0.065
... A41: Merge | B41: 200000 | C41: 5 | D41: 0.142000 | E41: 3263815 | F41: =VALUE(SUBSTITUTE(D41,".",",")) -> 0.142
A42: Bubble | B42: 500000 | C42: 1 | D42: 2108176000 | E42: 124999750000 | F42: 2108.176
A43: Bubble | B43: 500000 | C43: 2 | D43: 2075004000 | E43: 124999750000 | F43: 2075.004
A44: Bubble | B44: 500000 | C44: 3 | D44: 2088027000 | E44: 124999750000 | F44: 2088.027
A45: Bubble | B45: 500000 | C45: 4 | D45: 2192899000 | E45: 124999750000 | F45: 2192.899
A46: Bubble | B46: 500000 | C46: 5 | D46: 2205847000 | E46: 124999750000 | F46: 2205.847
A47: Merge | B47: 500000 | C47: 1 | D47: 0.488000 | E47: 8813340 | F47: =VALUE(SUBSTITUTE(D47,".",",")) -> 0.488
...

Sheet Tabela 1
A1: Alunos | B1: Bubble Sort (Média) | C1: Bubble Sort (DV) | D1: Merge Sort (Média) | E1: Merge Sort (DV)
A2: 1000 | B2: =AVERAGE(dados_brutos!F2:F6) -> 0.0056 | C2: =_xlfn.STDEV.S(dados_brutos!F2:F6) -> 0.00054772256 | D2: =AVERAGE(dados_brutos!F22:F26) -> 0.0008 | E2: =_xlfn.STDEV.S(dados_brutos!F22:F26) -> 0.0004472136
A3: 10000 | B3: =AVERAGE(dados_brutos!F7:F11) -> 0.5762 | C3: =_xlfn.STDEV.S(dados_brutos!F7:F11) -> 0.013608821 | D3: =AVERAGE(dados_brutos!F27:F31) -> 0.0058 | E3: =_xlfn.STDEV.S(dados_brutos!F27:F31) -> 0.0004472136
A4: 100000 | B4: =AVERAGE(dados_brutos!F12:F16) -> 84.4744 | C4: =_xlfn.STDEV.S(dados_brutos!F12:F16) -> 5.8055311 | D4: =AVERAGE(dados_brutos!F32:F36) -> 0.0656 | E4: =_xlfn.STDEV.S(dados_brutos!F32:F36) -> 0.0049799598
A5: 200000 | B5: =AVERAGE(dados_brutos!F17:F21) -> 363.4952 | C5: =_xlfn.STDEV.S(dados_brutos!F17:F21) -> 5.7437732 | D5: =AVERAGE(dados_brutos!F37:F41) -> 0.145 | E5: =_xlfn.STDEV.S(dados_brutos!F37:F41) -> 0.0029154759
A6: 500000 | B6: =AVERAGE(dados_brutos!F42:F46) -> 2133.9906 | C6: =_xlfn.STDEV.S(dados_brutos!F42:F46) -> 61.016405 | D6: =AVERAGE(dados_brutos!F47:F51) -> 0.456 | E6: =_xlfn.STDEV.S(dados_brutos!F47:F51) -> 0.047838269

Sheet Tabela 2
A1: Alunos | B1: Bubble Sort - Medido (Média) | C1: Bubble Sort - Medido (DV) | D1: Bubble Sort - Teórico O(n^2) | E1: Merge Sort - Medido (Média) | F1: Merge Sort - Medido (DV) | G1: Merge Sort - Teórico (O n log n)
A2: 1000 | B2: =AVERAGE(dados_brutos!E2:E6) -> 499500 | C2: =_xlfn.STDEV.S(dados_brutos!E2:E6) -> 0 | D2: ='Tabela 1'!A2^2 -> 1000000 | E2: =AVERAGE(dados_brutos!E22:E26) -> 8694.6 | F2: =_xlfn.STDEV.S(dados_brutos!E22:E26) -> 16.637307 | G2: ='Tabela 1'!A2*(LOG('Tabela 1'!A2,2)) -> 9965.7843
A3: 10000 | B3: =AVERAGE(dados_brutos!E7:E11) -> 49995000 | C3: =_xlfn.STDEV.S(dados_brutos!E7:E11) -> 0 | D3: ='Tabela 1'!A3^2 -> 100000000 | E3: =AVERAGE(dados_brutos!E27:E31) -> 120281.8 | F3: =_xlfn.STDEV.S(dados_brutos!E27:E31) -> 92.761522 | G3: ='Tabela 1'!A3*(LOG('Tabela 1'!A3,2)) -> 132877.12
A4: 100000 | B4: =AVERAGE(dados_brutos!E12:E16) -> 4999950000 | C4: =_xlfn.STDEV.S(dados_brutos!E12:E16) -> 0 | D4: ='Tabela 1'!A4^2 -> 10000000000 | E4: =AVERAGE(dados_brutos!E32:E36) -> 1532760.2 | F4: =_xlfn.STDEV.S(dados_brutos!E32:E36) -> 318.62156 | G4: ='Tabela 1'!A4*(LOG('Tabela 1'!A4,2)) -> 1660964
A5: 200000 | B5: =AVERAGE(dados_brutos!E17:E21) -> 19999900000 | C5: =_xlfn.STDEV.S(dados_brutos!E17:E21) -> 0 | D5: ='Tabela 1'!A5^2 -> 40000000000 | E5: =AVERAGE(dados_brutos!E37:E41) -> 3264479 | F5: =_xlfn.STDEV.S(dados_brutos!E37:E41) -> 391.87498 | G5: ='Tabela 1'!A5*(LOG('Tabela 1'!A5,2)) -> 3521928.1
A6: 500000 | B6: =AVERAGE(dados_brutos!E42:E46) -> 124999750000 | C6: =_xlfn.STDEV.S(dados_brutos!E42:E46) -> 0 | D6: ='Tabela 1'!A6^2 -> 250000000000 | E6: =AVERAGE(dados_brutos!E47:E51) -> 8812929 | F6: =_xlfn.STDEV.S(dados_brutos!E47:E51) -> 276.98285 | G6: ='Tabela 1'!A6*(LOG('Tabela 1'!A6,2)) -> 9465784.3
B14: Alunos | C14: Bubble Sort - Medido (Média) | D14: Merge Sort - Medido (Média)
B15: 1000 | C15: 499500 | D15: 8694.6
B16: 10000 | C16: 49995000 | D16: 120281.8
B17: 100000 | C17: 4999950000 | D17: 1532760.2
B18: 200000 | C18: 19999900000 | D18: 3264479
B19: 500000 | C19: 124999750000 | D19: 8812929
